

local S = lib_mg_continental.intllib


	local mgparams = minetest.get_mapgen_params()
	local mg_seed = mgparams.seed

	local __ = {name = "air",param2 = 0,prob = 0}
	local aa = {name = "air",param2 = 0,prob = 254, force_place = true}
	local WW = {name = "lib_materials:liquid_water_river_source", param2 = 0, prob = 254, force_place = true}

	lib_mg_continental.river_13x = {
		size = {x = 13, y = 17, z = 13},
		data = {
			__, __, __, __, __, __, __, __, __, __, __, __, __,
			__, __, __, __, __, __, __, __, __, __, __, __, __,
			__, __, __, __, __, __, __, __, __, __, __, __, __,
			__, __, __, __, __, __, __, __, __, __, __, __, __,
			__, __, __, __, __, __, __, __, __, __, __, __, __,
			__, __, __, __, __, __, __, __, __, __, __, __, __,
			__, __, __, __, __, __, __, __, __, __, __, __, __,
			__, __, aa, aa, aa, aa, aa, aa, aa, aa, aa, __, __,
			__, aa, aa, aa, aa, aa, aa, aa, aa, aa, aa, aa, __,
			aa, aa, aa, aa, aa, aa, aa, aa, aa, aa, aa, aa, aa,
			aa, aa, aa, aa, aa, aa, aa, aa, aa, aa, aa, aa, aa,
			aa, aa, aa, aa, aa, aa, aa, aa, aa, aa, aa, aa, aa,
			aa, aa, aa, aa, aa, aa, aa, aa, aa, aa, aa, aa, aa,
			aa, aa, aa, aa, aa, aa, aa, aa, aa, aa, aa, aa, aa,
			__, __, __, __, __, __, __, __, __, __, __, __, __,				--1
			__, __, __, __, __, __, __, __, __, __, __, __, __,
			__, __, __, __, __, __, __, __, __, __, __, __, __,

			__, __, __, __, __, __, __, __, __, __, __, __, __,
			__, __, WW, WW, WW, WW, WW, WW, WW, WW, WW, __, __,
			__, __, WW, WW, WW, WW, WW, WW, WW, WW, WW, __, __,
			__, __, WW, WW, WW, WW, WW, WW, WW, WW, WW, __, __,
			__, __, WW, WW, WW, WW, WW, WW, WW, WW, WW, __, __,
			__, __, WW, WW, WW, WW, WW, WW, WW, WW, WW, __, __,
			__, __, WW, WW, WW, WW, WW, WW, WW, WW, WW, __, __,
			__, __, aa, aa, aa, aa, aa, aa, aa, aa, aa, __, __,
			__, aa, aa, aa, aa, aa, aa, aa, aa, aa, aa, aa, __,
			aa, aa, aa, aa, aa, aa, aa, aa, aa, aa, aa, aa, aa,
			aa, aa, aa, aa, aa, aa, aa, aa, aa, aa, aa, aa, aa,
			aa, aa, aa, aa, aa, aa, aa, aa, aa, aa, aa, aa, aa,
			aa, aa, aa, aa, aa, aa, aa, aa, aa, aa, aa, aa, aa,
			aa, aa, aa, aa, aa, aa, aa, aa, aa, aa, aa, aa, aa,
			__, __, __, __, __, __, __, __, __, __, __, __, __,				--2
			__, __, __, __, __, __, __, __, __, __, __, __, __,
			__, __, __, __, __, __, __, __, __, __, __, __, __,

			__, __, __, __, __, __, __, __, __, __, __, __, __,
			__, __, WW, WW, WW, WW, WW, WW, WW, WW, WW, __, __,
			__, __, WW, WW, WW, WW, WW, WW, WW, WW, WW, __, __,
			__, __, WW, WW, WW, WW, WW, WW, WW, WW, WW, __, __,
			__, __, WW, WW, WW, WW, WW, WW, WW, WW, WW, __, __,
			__, __, WW, WW, WW, WW, WW, WW, WW, WW, WW, __, __,
			__, __, WW, WW, WW, WW, WW, WW, WW, WW, WW, __, __,
			__, __, aa, aa, aa, aa, aa, aa, aa, aa, aa, __, __,
			__, aa, aa, aa, aa, aa, aa, aa, aa, aa, aa, aa, __,
			aa, aa, aa, aa, aa, aa, aa, aa, aa, aa, aa, aa, aa,
			aa, aa, aa, aa, aa, aa, aa, aa, aa, aa, aa, aa, aa,
			aa, aa, aa, aa, aa, aa, aa, aa, aa, aa, aa, aa, aa,
			aa, aa, aa, aa, aa, aa, aa, aa, aa, aa, aa, aa, aa,
			aa, aa, aa, aa, aa, aa, aa, aa, aa, aa, aa, aa, aa,
			__, __, __, __, __, __, __, __, __, __, __, __, __,
			__, __, __, __, __, __, __, __, __, __, __, __, __,
			__, __, __, __, __, __, __, __, __, __, __, __, __,

			__, __, __, WW, WW, WW, WW, WW, WW, WW, __, __, __,
			__, __, WW, WW, WW, WW, WW, WW, WW, WW, WW, __, __,
			__, __, WW, WW, WW, WW, WW, WW, WW, WW, WW, __, __,
			__, __, WW, WW, WW, WW, WW, WW, WW, WW, WW, __, __,
			__, __, WW, WW, WW, WW, WW, WW, WW, WW, WW, __, __,
			__, __, WW, WW, WW, WW, WW, WW, WW, WW, WW, __, __,
			__, __, WW, WW, WW, WW, WW, WW, WW, WW, WW, __, __,
			__, __, aa, aa, aa, aa, aa, aa, aa, aa, aa, __, __,
			__, aa, aa, aa, aa, aa, aa, aa, aa, aa, aa, aa, __,
			aa, aa, aa, aa, aa, aa, aa, aa, aa, aa, aa, aa, aa,
			aa, aa, aa, aa, aa, aa, aa, aa, aa, aa, aa, aa, aa,
			aa, aa, aa, aa, aa, aa, aa, aa, aa, aa, aa, aa, aa,
			aa, aa, aa, aa, aa, aa, aa, aa, aa, aa, aa, aa, aa,
			aa, aa, aa, aa, aa, aa, aa, aa, aa, aa, aa, aa, aa,
			__, __, __, __, __, __, __, __, __, __, __, __, __,
			__, __, __, __, __, __, __, __, __, __, __, __, __,
			__, __, __, __, __, __, __, __, __, __, __, __, __,

			__, __, __, WW, WW, WW, WW, WW, WW, WW, __, __, __,
			__, __, WW, WW, WW, WW, WW, WW, WW, WW, WW, __, __,
			__, __, WW, WW, WW, WW, WW, WW, WW, WW, WW, __, __,
			__, __, WW, WW, WW, WW, WW, WW, WW, WW, WW, __, __,
			__, __, WW, WW, WW, WW, WW, WW, WW, WW, WW, __, __,
			__, __, WW, WW, WW, WW, WW, WW, WW, WW, WW, __, __,
			__, __, WW, WW, WW, WW, WW, WW, WW, WW, WW, __, __,
			__, __, aa, aa, aa, aa, aa, aa, aa, aa, aa, __, __,
			__, aa, aa, aa, aa, aa, aa, aa, aa, aa, aa, aa, __,
			aa, aa, aa, aa, aa, aa, aa, aa, aa, aa, aa, aa, aa,
			aa, aa, aa, aa, aa, aa, aa, aa, aa, aa, aa, aa, aa,
			aa, aa, aa, aa, aa, aa, aa, aa, aa, aa, aa, aa, aa,
			aa, aa, aa, aa, aa, aa, aa, aa, aa, aa, aa, aa, aa,
			aa, aa, aa, aa, aa, aa, aa, aa, aa, aa, aa, aa, aa,
			__, __, __, __, __, __, __, __, __, __, __, __, __,
			__, __, __, __, __, __, __, __, __, __, __, __, __,
			__, __, __, __, __, __, __, __, __, __, __, __, __,

			__, __, __, WW, WW, WW, WW, WW, WW, WW, __, __, __,
			__, __, WW, WW, WW, WW, WW, WW, WW, WW, WW, __, __,
			__, __, WW, WW, WW, WW, WW, WW, WW, WW, WW, __, __,
			__, __, WW, WW, WW, WW, WW, WW, WW, WW, WW, __, __,
			__, __, WW, WW, WW, WW, WW, WW, WW, WW, WW, __, __,
			__, __, WW, WW, WW, WW, WW, WW, WW, WW, WW, __, __,
			__, __, WW, WW, WW, WW, WW, WW, WW, WW, WW, __, __,
			__, __, aa, aa, aa, aa, aa, aa, aa, aa, aa, __, __,
			__, aa, aa, aa, aa, aa, aa, aa, aa, aa, aa, aa, __,
			aa, aa, aa, aa, aa, aa, aa, aa, aa, aa, aa, aa, aa,
			aa, aa, aa, aa, aa, aa, aa, aa, aa, aa, aa, aa, aa,
			aa, aa, aa, aa, aa, aa, aa, aa, aa, aa, aa, aa, aa,
			aa, aa, aa, aa, aa, aa, aa, aa, aa, aa, aa, aa, aa,
			aa, aa, aa, aa, aa, aa, aa, aa, aa, aa, aa, aa, aa,
			__, __, __, __, __, __, __, __, __, __, __, __, __,
			__, __, __, __, __, __, __, __, __, __, __, __, __,
			__, __, __, __, __, __, __, __, __, __, __, __, __,

			__, __, __, WW, WW, WW, WW, WW, WW, WW, __, __, __,
			__, __, WW, WW, WW, WW, WW, WW, WW, WW, WW, __, __,
			__, __, WW, WW, WW, WW, WW, WW, WW, WW, WW, __, __,
			__, __, WW, WW, WW, WW, WW, WW, WW, WW, WW, __, __,
			__, __, WW, WW, WW, WW, WW, WW, WW, WW, WW, __, __,
			__, __, WW, WW, WW, WW, WW, WW, WW, WW, WW, __, __,
			__, __, WW, WW, WW, WW, WW, WW, WW, WW, WW, __, __,
			__, __, aa, aa, aa, aa, aa, aa, aa, aa, aa, __, __,
			__, aa, aa, aa, aa, aa, aa, aa, aa, aa, aa, aa, __,
			aa, aa, aa, aa, aa, aa, aa, aa, aa, aa, aa, aa, aa,
			aa, aa, aa, aa, aa, aa, aa, aa, aa, aa, aa, aa, aa,
			aa, aa, aa, aa, aa, aa, aa, aa, aa, aa, aa, aa, aa,
			aa, aa, aa, aa, aa, aa, aa, aa, aa, aa, aa, aa, aa,
			aa, aa, aa, aa, aa, aa, aa, aa, aa, aa, aa, aa, aa,
			__, __, __, __, __, __, __, __, __, __, __, __, __,
			__, __, __, __, __, __, __, __, __, __, __, __, __,
			__, __, __, __, __, __, __, __, __, __, __, __, __,

			__, __, __, WW, WW, WW, WW, WW, WW, WW, __, __, __,
			__, __, WW, WW, WW, WW, WW, WW, WW, WW, WW, __, __,
			__, __, WW, WW, WW, WW, WW, WW, WW, WW, WW, __, __,
			__, __, WW, WW, WW, WW, WW, WW, WW, WW, WW, __, __,
			__, __, WW, WW, WW, WW, WW, WW, WW, WW, WW, __, __,
			__, __, WW, WW, WW, WW, WW, WW, WW, WW, WW, __, __,
			__, __, WW, WW, WW, WW, WW, WW, WW, WW, WW, __, __,
			__, __, aa, aa, aa, aa, aa, aa, aa, aa, aa, __, __,
			__, aa, aa, aa, aa, aa, aa, aa, aa, aa, aa, aa, __,
			aa, aa, aa, aa, aa, aa, aa, aa, aa, aa, aa, aa, aa,
			aa, aa, aa, aa, aa, aa, aa, aa, aa, aa, aa, aa, aa,
			aa, aa, aa, aa, aa, aa, aa, aa, aa, aa, aa, aa, aa,
			aa, aa, aa, aa, aa, aa, aa, aa, aa, aa, aa, aa, aa,
			aa, aa, aa, aa, aa, aa, aa, aa, aa, aa, aa, aa, aa,
			__, __, __, __, __, __, __, __, __, __, __, __, __,
			__, __, __, __, __, __, __, __, __, __, __, __, __,
			__, __, __, __, __, __, __, __, __, __, __, __, __,

			__, __, __, WW, WW, WW, WW, WW, WW, WW, __, __, __,
			__, __, WW, WW, WW, WW, WW, WW, WW, WW, WW, __, __,
			__, __, WW, WW, WW, WW, WW, WW, WW, WW, WW, __, __,
			__, __, WW, WW, WW, WW, WW, WW, WW, WW, WW, __, __,
			__, __, WW, WW, WW, WW, WW, WW, WW, WW, WW, __, __,
			__, __, WW, WW, WW, WW, WW, WW, WW, WW, WW, __, __,
			__, __, WW, WW, WW, WW, WW, WW, WW, WW, WW, __, __,
			__, __, aa, aa, aa, aa, aa, aa, aa, aa, aa, __, __,
			__, aa, aa, aa, aa, aa, aa, aa, aa, aa, aa, aa, __,
			aa, aa, aa, aa, aa, aa, aa, aa, aa, aa, aa, aa, aa,
			aa, aa, aa, aa, aa, aa, aa, aa, aa, aa, aa, aa, aa,
			aa, aa, aa, aa, aa, aa, aa, aa, aa, aa, aa, aa, aa,
			aa, aa, aa, aa, aa, aa, aa, aa, aa, aa, aa, aa, aa,
			aa, aa, aa, aa, aa, aa, aa, aa, aa, aa, aa, aa, aa,
			__, __, __, __, __, __, __, __, __, __, __, __, __,
			__, __, __, __, __, __, __, __, __, __, __, __, __,
			__, __, __, __, __, __, __, __, __, __, __, __, __,

			__, __, __, WW, WW, WW, WW, WW, WW, WW, __, __, __,
			__, __, WW, WW, WW, WW, WW, WW, WW, WW, WW, __, __,
			__, __, WW, WW, WW, WW, WW, WW, WW, WW, WW, __, __,
			__, __, WW, WW, WW, WW, WW, WW, WW, WW, WW, __, __,
			__, __, WW, WW, WW, WW, WW, WW, WW, WW, WW, __, __,
			__, __, WW, WW, WW, WW, WW, WW, WW, WW, WW, __, __,
			__, __, WW, WW, WW, WW, WW, WW, WW, WW, WW, __, __,
			__, __, aa, aa, aa, aa, aa, aa, aa, aa, aa, __, __,
			__, aa, aa, aa, aa, aa, aa, aa, aa, aa, aa, aa, __,
			aa, aa, aa, aa, aa, aa, aa, aa, aa, aa, aa, aa, aa,
			aa, aa, aa, aa, aa, aa, aa, aa, aa, aa, aa, aa, aa,
			aa, aa, aa, aa, aa, aa, aa, aa, aa, aa, aa, aa, aa,
			aa, aa, aa, aa, aa, aa, aa, aa, aa, aa, aa, aa, aa,
			aa, aa, aa, aa, aa, aa, aa, aa, aa, aa, aa, aa, aa,
			__, __, __, __, __, __, __, __, __, __, __, __, __,
			__, __, __, __, __, __, __, __, __, __, __, __, __,
			__, __, __, __, __, __, __, __, __, __, __, __, __,

			__, __, __, __, __, __, __, __, __, __, __, __, __,
			__, __, WW, WW, WW, WW, WW, WW, WW, WW, WW, __, __,
			__, __, WW, WW, WW, WW, WW, WW, WW, WW, WW, __, __,
			__, __, WW, WW, WW, WW, WW, WW, WW, WW, WW, __, __,
			__, __, WW, WW, WW, WW, WW, WW, WW, WW, WW, __, __,
			__, __, WW, WW, WW, WW, WW, WW, WW, WW, WW, __, __,
			__, __, WW, WW, WW, WW, WW, WW, WW, WW, WW, __, __,
			__, __, aa, aa, aa, aa, aa, aa, aa, aa, aa, __, __,
			__, aa, aa, aa, aa, aa, aa, aa, aa, aa, aa, aa, __,
			aa, aa, aa, aa, aa, aa, aa, aa, aa, aa, aa, aa, aa,
			aa, aa, aa, aa, aa, aa, aa, aa, aa, aa, aa, aa, aa,
			aa, aa, aa, aa, aa, aa, aa, aa, aa, aa, aa, aa, aa,
			aa, aa, aa, aa, aa, aa, aa, aa, aa, aa, aa, aa, aa,
			aa, aa, aa, aa, aa, aa, aa, aa, aa, aa, aa, aa, aa,
			__, __, __, __, __, __, __, __, __, __, __, __, __,
			__, __, __, __, __, __, __, __, __, __, __, __, __,
			__, __, __, __, __, __, __, __, __, __, __, __, __,

			__, __, __, __, __, __, __, __, __, __, __, __, __,
			__, __, WW, WW, WW, WW, WW, WW, WW, WW, WW, __, __,
			__, __, WW, WW, WW, WW, WW, WW, WW, WW, WW, __, __,
			__, __, WW, WW, WW, WW, WW, WW, WW, WW, WW, __, __,
			__, __, WW, WW, WW, WW, WW, WW, WW, WW, WW, __, __,
			__, __, WW, WW, WW, WW, WW, WW, WW, WW, WW, __, __,
			__, __, WW, WW, WW, WW, WW, WW, WW, WW, WW, __, __,
			__, __, aa, aa, aa, aa, aa, aa, aa, aa, aa, __, __,
			__, aa, aa, aa, aa, aa, aa, aa, aa, aa, aa, aa, __,
			aa, aa, aa, aa, aa, aa, aa, aa, aa, aa, aa, aa, aa,
			aa, aa, aa, aa, aa, aa, aa, aa, aa, aa, aa, aa, aa,
			aa, aa, aa, aa, aa, aa, aa, aa, aa, aa, aa, aa, aa,
			aa, aa, aa, aa, aa, aa, aa, aa, aa, aa, aa, aa, aa,
			aa, aa, aa, aa, aa, aa, aa, aa, aa, aa, aa, aa, aa,
			__, __, __, __, __, __, __, __, __, __, __, __, __,
			__, __, __, __, __, __, __, __, __, __, __, __, __,
			__, __, __, __, __, __, __, __, __, __, __, __, __,

			__, __, __, __, __, __, __, __, __, __, __, __, __,
			__, __, __, __, __, __, __, __, __, __, __, __, __,
			__, __, __, __, __, __, __, __, __, __, __, __, __,
			__, __, __, __, __, __, __, __, __, __, __, __, __,
			__, __, __, __, __, __, __, __, __, __, __, __, __,
			__, __, __, __, __, __, __, __, __, __, __, __, __,
			__, __, __, __, __, __, __, __, __, __, __, __, __,
			__, __, aa, aa, aa, aa, aa, aa, aa, aa, aa, __, __,
			__, aa, aa, aa, aa, aa, aa, aa, aa, aa, aa, aa, __,
			aa, aa, aa, aa, aa, aa, aa, aa, aa, aa, aa, aa, aa,
			aa, aa, aa, aa, aa, aa, aa, aa, aa, aa, aa, aa, aa,
			aa, aa, aa, aa, aa, aa, aa, aa, aa, aa, aa, aa, aa,
			aa, aa, aa, aa, aa, aa, aa, aa, aa, aa, aa, aa, aa,
			aa, aa, aa, aa, aa, aa, aa, aa, aa, aa, aa, aa, aa,
			__, __, __, __, __, __, __, __, __, __, __, __, __,
			__, __, __, __, __, __, __, __, __, __, __, __, __,
			__, __, __, __, __, __, __, __, __, __, __, __, __
		},
		yslice_prob = {
			{ypos = 0,prob = 254},
			{ypos = 1,prob = 254},
			{ypos = 2,prob = 254},
			{ypos = 3,prob = 254},
			{ypos = 4,prob = 254},
			{ypos = 5,prob = 254},
			{ypos = 6,prob = 254},
			{ypos = 7,prob = 254},
			{ypos = 8,prob = 254},
			{ypos = 9,prob = 254},
			{ypos = 10,prob = 254},
			{ypos = 11,prob = 254},
			{ypos = 12,prob = 254},
			{ypos = 13,prob = 254},
			{ypos = 14,prob = 254},
			{ypos = 15,prob = 254},
			{ypos = 16,prob = 254}
		}
	}

	lib_mg_continental.river_11x = {
		size = {x = 11, y = 13, z = 11},
		data = {
			__, __, __, __, __, __, __, __, __, __, __,
			__, __, __, __, __, __, __, __, __, __, __,
			__, __, __, __, __, __, __, __, __, __, __,
			__, __, __, __, __, __, __, __, __, __, __,
			__, __, __, __, __, __, __, __, __, __, __,
			__, __, __, __, __, __, __, __, __, __, __,
			__, __, __, __, __, __, __, __, __, __, __,
			__, __, aa, aa, aa, aa, aa, aa, aa, __, __,
			__, aa, aa, aa, aa, aa, aa, aa, aa, aa, __,
			aa, aa, aa, aa, aa, aa, aa, aa, aa, aa, aa,
			aa, aa, aa, aa, aa, aa, aa, aa, aa, aa, aa,
			aa, aa, aa, aa, aa, aa, aa, aa, aa, aa, aa,
			aa, aa, aa, aa, aa, aa, aa, aa, aa, aa, aa,

			__, __, __, __, __, __, __, __, __, __, __,
			__, __, __, __, __, __, __, __, __, __, __,
			__, __, __, __, __, __, __, __, __, __, __,
			__, __, WW, WW, WW, WW, WW, WW, WW, __, __,
			__, __, WW, WW, WW, WW, WW, WW, WW, __, __,
			__, __, WW, WW, WW, WW, WW, WW, WW, __, __,
			__, __, WW, WW, WW, WW, WW, WW, WW, __, __,
			__, __, aa, aa, aa, aa, aa, aa, aa, __, __,
			__, aa, aa, aa, aa, aa, aa, aa, aa, aa, __,
			aa, aa, aa, aa, aa, aa, aa, aa, aa, aa, aa,
			aa, aa, aa, aa, aa, aa, aa, aa, aa, aa, aa,
			aa, aa, aa, aa, aa, aa, aa, aa, aa, aa, aa,
			aa, aa, aa, aa, aa, aa, aa, aa, aa, aa, aa,

			__, __, __, __, __, __, __, __, __, __, __,
			__, __, __, __, __, __, __, __, __, __, __,
			__, __, __, __, __, __, __, __, __, __, __,
			__, __, WW, WW, WW, WW, WW, WW, WW, __, __,
			__, __, WW, WW, WW, WW, WW, WW, WW, __, __,
			__, __, WW, WW, WW, WW, WW, WW, WW, __, __,
			__, __, WW, WW, WW, WW, WW, WW, WW, __, __,
			__, __, aa, aa, aa, aa, aa, aa, aa, __, __,
			__, aa, aa, aa, aa, aa, aa, aa, aa, aa, __,
			aa, aa, aa, aa, aa, aa, aa, aa, aa, aa, aa,
			aa, aa, aa, aa, aa, aa, aa, aa, aa, aa, aa,
			aa, aa, aa, aa, aa, aa, aa, aa, aa, aa, aa,
			aa, aa, aa, aa, aa, aa, aa, aa, aa, aa, aa,

			__, __, __, __, __, __, __, __, __, __, __,
			__, __, __, __, __, __, __, __, __, __, __,
			__, __, __, WW, WW, WW, WW, WW, __, __, __,
			__, __, WW, WW, WW, WW, WW, WW, WW, __, __,
			__, __, WW, WW, WW, WW, WW, WW, WW, __, __,
			__, __, WW, WW, WW, WW, WW, WW, WW, __, __,
			__, __, WW, WW, WW, WW, WW, WW, WW, __, __,
			__, __, aa, aa, aa, aa, aa, aa, aa, __, __,
			__, aa, aa, aa, aa, aa, aa, aa, aa, aa, __,
			aa, aa, aa, aa, aa, aa, aa, aa, aa, aa, aa,
			aa, aa, aa, aa, aa, aa, aa, aa, aa, aa, aa,
			aa, aa, aa, aa, aa, aa, aa, aa, aa, aa, aa,
			aa, aa, aa, aa, aa, aa, aa, aa, aa, aa, aa,

			__, __, __, __, __, __, __, __, __, __, __,
			__, __, __, __, WW, WW, WW, __, __, __, __,
			__, __, __, WW, WW, WW, WW, WW, __, __, __,
			__, __, WW, WW, WW, WW, WW, WW, WW, __, __,
			__, __, WW, WW, WW, WW, WW, WW, WW, __, __,
			__, __, WW, WW, WW, WW, WW, WW, WW, __, __,
			__, __, WW, WW, WW, WW, WW, WW, WW, __, __,
			__, __, aa, aa, aa, aa, aa, aa, aa, __, __,
			__, aa, aa, aa, aa, aa, aa, aa, aa, aa, __,
			aa, aa, aa, aa, aa, aa, aa, aa, aa, aa, aa,
			aa, aa, aa, aa, aa, aa, aa, aa, aa, aa, aa,
			aa, aa, aa, aa, aa, aa, aa, aa, aa, aa, aa,
			aa, aa, aa, aa, aa, aa, aa, aa, aa, aa, aa,

			__, __, __, __, __, __, __, __, __, __, __,
			__, __, __, __, WW, WW, WW, __, __, __, __,
			__, __, __, WW, WW, WW, WW, WW, __, __, __,
			__, __, WW, WW, WW, WW, WW, WW, WW, __, __,
			__, __, WW, WW, WW, WW, WW, WW, WW, __, __,
			__, __, WW, WW, WW, WW, WW, WW, WW, __, __,
			__, __, WW, WW, WW, WW, WW, WW, WW, __, __,
			__, __, aa, aa, aa, aa, aa, aa, aa, __, __,
			__, aa, aa, aa, aa, aa, aa, aa, aa, aa, __,
			aa, aa, aa, aa, aa, aa, aa, aa, aa, aa, aa,
			aa, aa, aa, aa, aa, aa, aa, aa, aa, aa, aa,
			aa, aa, aa, aa, aa, aa, aa, aa, aa, aa, aa,
			aa, aa, aa, aa, aa, aa, aa, aa, aa, aa, aa,

			__, __, __, __, __, __, __, __, __, __, __,
			__, __, __, __, WW, WW, WW, __, __, __, __,
			__, __, __, WW, WW, WW, WW, WW, __, __, __,
			__, __, WW, WW, WW, WW, WW, WW, WW, __, __,
			__, __, WW, WW, WW, WW, WW, WW, WW, __, __,
			__, __, WW, WW, WW, WW, WW, WW, WW, __, __,
			__, __, WW, WW, WW, WW, WW, WW, WW, __, __,
			__, __, aa, aa, aa, aa, aa, aa, aa, __, __,
			__, aa, aa, aa, aa, aa, aa, aa, aa, aa, __,
			aa, aa, aa, aa, aa, aa, aa, aa, aa, aa, aa,
			aa, aa, aa, aa, aa, aa, aa, aa, aa, aa, aa,
			aa, aa, aa, aa, aa, aa, aa, aa, aa, aa, aa,
			aa, aa, aa, aa, aa, aa, aa, aa, aa, aa, aa,

			__, __, __, __, __, __, __, __, __, __, __,
			__, __, __, __, __, __, __, __, __, __, __,
			__, __, __, WW, WW, WW, WW, WW, __, __, __,
			__, __, WW, WW, WW, WW, WW, WW, WW, __, __,
			__, __, WW, WW, WW, WW, WW, WW, WW, __, __,
			__, __, WW, WW, WW, WW, WW, WW, WW, __, __,
			__, __, WW, WW, WW, WW, WW, WW, WW, __, __,
			__, __, aa, aa, aa, aa, aa, aa, aa, __, __,
			__, aa, aa, aa, aa, aa, aa, aa, aa, aa, __,
			aa, aa, aa, aa, aa, aa, aa, aa, aa, aa, aa,
			aa, aa, aa, aa, aa, aa, aa, aa, aa, aa, aa,
			aa, aa, aa, aa, aa, aa, aa, aa, aa, aa, aa,
			aa, aa, aa, aa, aa, aa, aa, aa, aa, aa, aa,

			__, __, __, __, __, __, __, __, __, __, __,
			__, __, __, __, __, __, __, __, __, __, __,
			__, __, __, __, __, __, __, __, __, __, __,
			__, __, WW, WW, WW, WW, WW, WW, WW, __, __,
			__, __, WW, WW, WW, WW, WW, WW, WW, __, __,
			__, __, WW, WW, WW, WW, WW, WW, WW, __, __,
			__, __, WW, WW, WW, WW, WW, WW, WW, __, __,
			__, __, aa, aa, aa, aa, aa, aa, aa, __, __,
			__, aa, aa, aa, aa, aa, aa, aa, aa, aa, __,
			aa, aa, aa, aa, aa, aa, aa, aa, aa, aa, aa,
			aa, aa, aa, aa, aa, aa, aa, aa, aa, aa, aa,
			aa, aa, aa, aa, aa, aa, aa, aa, aa, aa, aa,
			aa, aa, aa, aa, aa, aa, aa, aa, aa, aa, aa,

			__, __, __, __, __, __, __, __, __, __, __,
			__, __, __, __, __, __, __, __, __, __, __,
			__, __, __, __, __, __, __, __, __, __, __,
			__, __, WW, WW, WW, WW, WW, WW, WW, __, __,
			__, __, WW, WW, WW, WW, WW, WW, WW, __, __,
			__, __, WW, WW, WW, WW, WW, WW, WW, __, __,
			__, __, WW, WW, WW, WW, WW, WW, WW, __, __,
			__, __, aa, aa, aa, aa, aa, aa, aa, __, __,
			__, aa, aa, aa, aa, aa, aa, aa, aa, aa, __,
			aa, aa, aa, aa, aa, aa, aa, aa, aa, aa, aa,
			aa, aa, aa, aa, aa, aa, aa, aa, aa, aa, aa,
			aa, aa, aa, aa, aa, aa, aa, aa, aa, aa, aa,
			aa, aa, aa, aa, aa, aa, aa, aa, aa, aa, aa,

			__, __, __, __, __, __, __, __, __, __, __,
			__, __, __, __, __, __, __, __, __, __, __,
			__, __, __, __, __, __, __, __, __, __, __,
			__, __, __, __, __, __, __, __, __, __, __,
			__, __, __, __, __, __, __, __, __, __, __,
			__, __, __, __, __, __, __, __, __, __, __,
			__, __, __, __, __, __, __, __, __, __, __,
			__, __, aa, aa, aa, aa, aa, aa, aa, __, __,
			__, aa, aa, aa, aa, aa, aa, aa, aa, aa, __,
			aa, aa, aa, aa, aa, aa, aa, aa, aa, aa, aa,
			aa, aa, aa, aa, aa, aa, aa, aa, aa, aa, aa,
			aa, aa, aa, aa, aa, aa, aa, aa, aa, aa, aa,
			aa, aa, aa, aa, aa, aa, aa, aa, aa, aa, aa,
		},
		yslice_prob = {
			{ypos = 0,prob = 254},
			{ypos = 1,prob = 254},
			{ypos = 2,prob = 254},
			{ypos = 3,prob = 254},
			{ypos = 4,prob = 254},
			{ypos = 5,prob = 254},
			{ypos = 6,prob = 254},
			{ypos = 7,prob = 254},
			{ypos = 8,prob = 254},
			{ypos = 9,prob = 254},
			{ypos = 10,prob = 254},
			{ypos = 11,prob = 254},
			{ypos = 12,prob = 254}
		}
	}

	lib_mg_continental.river_9x = {
		size = {x = 9, y = 11, z = 9},
		data = {
			__, __, __, __, __, __, __, __, __,
			__, __, __, __, __, __, __, __, __,
			__, __, __, __, __, __, __, __, __,
			__, __, __, __, __, __, __, __, __,
			__, __, __, __, __, __, __, __, __,
			__, __, aa, aa, aa, aa, aa, __, __,
			__, aa, aa, aa, aa, aa, aa, aa, __,
			aa, aa, aa, aa, aa, aa, aa, aa, aa,
			aa, aa, aa, aa, aa, aa, aa, aa, aa,
			aa, aa, aa, aa, aa, aa, aa, aa, aa,
			aa, aa, aa, aa, aa, aa, aa, aa, aa,

			__, __, __, __, __, __, __, __, __,
			__, __, __, __, __, __, __, __, __,
			__, __, WW, WW, WW, WW, WW, __, __,
			__, __, WW, WW, WW, WW, WW, __, __,
			__, __, WW, WW, WW, WW, WW, __, __,
			__, __, aa, aa, aa, aa, aa, __, __,
			__, aa, aa, aa, aa, aa, aa, aa, __,
			aa, aa, aa, aa, aa, aa, aa, aa, aa,
			aa, aa, aa, aa, aa, aa, aa, aa, aa,
			aa, aa, aa, aa, aa, aa, aa, aa, aa,
			aa, aa, aa, aa, aa, aa, aa, aa, aa,

			__, __, __, __, __, __, __, __, __,
			__, __, __, __, __, __, __, __, __,
			__, __, WW, WW, WW, WW, WW, __, __,
			__, __, WW, WW, WW, WW, WW, __, __,
			__, __, WW, WW, WW, WW, WW, __, __,
			__, __, aa, aa, aa, aa, aa, __, __,
			__, aa, aa, aa, aa, aa, aa, aa, __,
			aa, aa, aa, aa, aa, aa, aa, aa, aa,
			aa, aa, aa, aa, aa, aa, aa, aa, aa,
			aa, aa, aa, aa, aa, aa, aa, aa, aa,
			aa, aa, aa, aa, aa, aa, aa, aa, aa,

			__, __, __, __, __, __, __, __, __,
			__, __, __, WW, WW, WW, __, __, __,
			__, __, WW, WW, WW, WW, WW, __, __,
			__, __, WW, WW, WW, WW, WW, __, __,
			__, __, WW, WW, WW, WW, WW, __, __,
			__, __, aa, aa, aa, aa, aa, __, __,
			__, aa, aa, aa, aa, aa, aa, aa, __,
			aa, aa, aa, aa, aa, aa, aa, aa, aa,
			aa, aa, aa, aa, aa, aa, aa, aa, aa,
			aa, aa, aa, aa, aa, aa, aa, aa, aa,
			aa, aa, aa, aa, aa, aa, aa, aa, aa,

			__, __, __, __, __, __, __, __, __,
			__, __, __, WW, WW, WW, __, __, __,
			__, __, WW, WW, WW, WW, WW, __, __,
			__, __, WW, WW, WW, WW, WW, __, __,
			__, __, WW, WW, WW, WW, WW, __, __,
			__, __, aa, aa, aa, aa, aa, __, __,
			__, aa, aa, aa, aa, aa, aa, aa, __,
			aa, aa, aa, aa, aa, aa, aa, aa, aa,
			aa, aa, aa, aa, aa, aa, aa, aa, aa,
			aa, aa, aa, aa, aa, aa, aa, aa, aa,
			aa, aa, aa, aa, aa, aa, aa, aa, aa,

			__, __, __, __, __, __, __, __, __,
			__, __, __, WW, WW, WW, __, __, __,
			__, __, WW, WW, WW, WW, WW, __, __,
			__, __, WW, WW, WW, WW, WW, __, __,
			__, __, WW, WW, WW, WW, WW, __, __,
			__, __, aa, aa, aa, aa, aa, __, __,
			__, aa, aa, aa, aa, aa, aa, aa, __,
			aa, aa, aa, aa, aa, aa, aa, aa, aa,
			aa, aa, aa, aa, aa, aa, aa, aa, aa,
			aa, aa, aa, aa, aa, aa, aa, aa, aa,
			aa, aa, aa, aa, aa, aa, aa, aa, aa,

			__, __, __, __, __, __, __, __, __,
			__, __, __, __, __, __, __, __, __,
			__, __, WW, WW, WW, WW, WW, __, __,
			__, __, WW, WW, WW, WW, WW, __, __,
			__, __, WW, WW, WW, WW, WW, __, __,
			__, __, aa, aa, aa, aa, aa, __, __,
			__, aa, aa, aa, aa, aa, aa, aa, __,
			aa, aa, aa, aa, aa, aa, aa, aa, aa,
			aa, aa, aa, aa, aa, aa, aa, aa, aa,
			aa, aa, aa, aa, aa, aa, aa, aa, aa,
			aa, aa, aa, aa, aa, aa, aa, aa, aa,

			__, __, __, __, __, __, __, __, __,
			__, __, __, __, __, __, __, __, __,
			__, __, WW, WW, WW, WW, WW, __, __,
			__, __, WW, WW, WW, WW, WW, __, __,
			__, __, WW, WW, WW, WW, WW, __, __,
			__, __, aa, aa, aa, aa, aa, __, __,
			__, aa, aa, aa, aa, aa, aa, aa, __,
			aa, aa, aa, aa, aa, aa, aa, aa, aa,
			aa, aa, aa, aa, aa, aa, aa, aa, aa,
			aa, aa, aa, aa, aa, aa, aa, aa, aa,
			aa, aa, aa, aa, aa, aa, aa, aa, aa,

			__, __, __, __, __, __, __, __, __,
			__, __, __, __, __, __, __, __, __,
			__, __, __, __, __, __, __, __, __,
			__, __, __, __, __, __, __, __, __,
			__, __, __, __, __, __, __, __, __,
			__, __, aa, aa, aa, aa, aa, __, __,
			__, aa, aa, aa, aa, aa, aa, aa, __,
			aa, aa, aa, aa, aa, aa, aa, aa, aa,
			aa, aa, aa, aa, aa, aa, aa, aa, aa,
			aa, aa, aa, aa, aa, aa, aa, aa, aa,
			aa, aa, aa, aa, aa, aa, aa, aa, aa
		},
		yslice_prob = {
			{ypos = 0,prob = 254},
			{ypos = 1,prob = 254},
			{ypos = 2,prob = 254},
			{ypos = 3,prob = 254},
			{ypos = 4,prob = 254},
			{ypos = 5,prob = 254},
			{ypos = 6,prob = 254},
			{ypos = 7,prob = 254},
			{ypos = 8,prob = 254},
			{ypos = 9,prob = 254},
			{ypos = 10,prob = 254}
		}
	}

	lib_mg_continental.river_7x = {
		size = {x = 7, y = 11, z = 7},
		data = {
			__, __, __, __, __, __, __,
			__, __, __, __, __, __, __,
			__, __, __, __, __, __, __,
			__, __, __, __, __, __, __,
			__, __, aa, aa, aa, __, __,
			__, __, aa, aa, aa, __, __,
			__, aa, aa, aa, aa, aa, __,
			aa, aa, aa, aa, aa, aa, aa,
			aa, aa, aa, aa, aa, aa, aa,
			aa, aa, aa, aa, aa, aa, aa,
			aa, aa, aa, aa, aa, aa, aa,

			__, __, __, __, __, __, __,
			__, __, __, __, __, __, __,
			__, __, WW, WW, WW, __, __,
			__, __, WW, WW, WW, __, __,
			__, __, WW, WW, WW, __, __,
			__, __, aa, aa, aa, __, __,
			__, aa, aa, aa, aa, aa, __,
			aa, aa, aa, aa, aa, aa, aa,
			aa, aa, aa, aa, aa, aa, aa,
			aa, aa, aa, aa, aa, aa, aa,
			aa, aa, aa, aa, aa, aa, aa,

			__, __, __, __, __, __, __,
			__, __, __, __, __, __, __,
			__, __, WW, WW, WW, __, __,
			__, __, WW, WW, WW, __, __,
			__, __, WW, WW, WW, __, __,
			__, __, aa, aa, aa, __, __,
			__, aa, aa, aa, aa, aa, __,
			aa, aa, aa, aa, aa, aa, aa,
			aa, aa, aa, aa, aa, aa, aa,
			aa, aa, aa, aa, aa, aa, aa,
			aa, aa, aa, aa, aa, aa, aa,

			__, __, __, __, __, __, __,
			__, __, __, WW, __, __, __,
			__, __, WW, WW, WW, __, __,
			__, __, WW, WW, WW, __, __,
			__, __, WW, WW, WW, __, __,
			__, __, aa, aa, aa, __, __,
			__, aa, aa, aa, aa, aa, __,
			aa, aa, aa, aa, aa, aa, aa,
			aa, aa, aa, aa, aa, aa, aa,
			aa, aa, aa, aa, aa, aa, aa,
			aa, aa, aa, aa, aa, aa, aa,

			__, __, __, __, __, __, __,
			__, __, __, __, __, __, __,
			__, __, WW, WW, WW, __, __,
			__, __, WW, WW, WW, __, __,
			__, __, WW, WW, WW, __, __,
			__, __, aa, aa, aa, __, __,
			__, aa, aa, aa, aa, aa, __,
			aa, aa, aa, aa, aa, aa, aa,
			aa, aa, aa, aa, aa, aa, aa,
			aa, aa, aa, aa, aa, aa, aa,
			aa, aa, aa, aa, aa, aa, aa,

			__, __, __, __, __, __, __,
			__, __, __, __, __, __, __,
			__, __, WW, WW, WW, __, __,
			__, __, WW, WW, WW, __, __,
			__, __, WW, WW, WW, __, __,
			__, __, aa, aa, aa, __, __,
			__, aa, aa, aa, aa, aa, __,
			aa, aa, aa, aa, aa, aa, aa,
			aa, aa, aa, aa, aa, aa, aa,
			aa, aa, aa, aa, aa, aa, aa,
			aa, aa, aa, aa, aa, aa, aa,

			__, __, __, __, __, __, __,
			__, __, __, __, __, __, __,
			__, __, __, __, __, __, __,
			__, __, __, __, __, __, __,
			__, __, aa, aa, aa, __, __,
			__, __, aa, aa, aa, __, __,
			__, aa, aa, aa, aa, aa, __,
			aa, aa, aa, aa, aa, aa, aa,
			aa, aa, aa, aa, aa, aa, aa,
			aa, aa, aa, aa, aa, aa, aa,
			aa, aa, aa, aa, aa, aa, aa,
		},
		yslice_prob = {
			{ypos = 0,prob = 254},
			{ypos = 1,prob = 254},
			{ypos = 2,prob = 254},
			{ypos = 3,prob = 254},
			{ypos = 4,prob = 254},
			{ypos = 5,prob = 254},
			{ypos = 6,prob = 254},
			{ypos = 7,prob = 254},
			{ypos = 8,prob = 254},
			{ypos = 9,prob = 254},
			{ypos = 10,prob = 254}
		}
	}

	lib_mg_continental.river_5x = {
		size = {x = 5, y = 9, z = 5},
		data = {
			__, __, __, __, __,
			__, __, __, __, __,
			__, __, __, __, __,
			__, __, __, __, __,
			__, aa, aa, aa, __,
			aa, aa, aa, aa, aa,
			aa, aa, aa, aa, aa,
			aa, aa, aa, aa, aa,
			aa, aa, aa, aa, aa,

			__, __, __, __, __,
			__, WW, WW, __, __,
			__, WW, WW, WW, __,
			__, WW, WW, WW, __,
			__, aa, aa, aa, __,
			aa, aa, aa, aa, aa,
			aa, aa, aa, aa, aa,
			aa, aa, aa, aa, aa,
			aa, aa, aa, aa, aa,

			__, __, __, __, __,
			__, WW, WW, WW, __,
			__, WW, WW, WW, __,
			__, WW, WW, WW, __,
			__, aa, aa, aa, __,
			aa, aa, aa, aa, aa,
			aa, aa, aa, aa, aa,
			aa, aa, aa, aa, aa,
			aa, aa, aa, aa, aa,

			__, __, __, __, __,
			__, __, WW, WW, __,
			__, WW, WW, WW, __,
			__, WW, WW, WW, __,
			__, aa, aa, aa, __,
			aa, aa, aa, aa, aa,
			aa, aa, aa, aa, aa,
			aa, aa, aa, aa, aa,
			aa, aa, aa, aa, aa,

			__, __, __, __, __,
			__, __, __, __, __,
			__, __, __, __, __,
			__, __, __, __, __,
			__, aa, aa, aa, __,
			aa, aa, aa, aa, aa,
			aa, aa, aa, aa, aa,
			aa, aa, aa, aa, aa,
			aa, aa, aa, aa, aa
		},
		yslice_prob = {
			{ypos = 0,prob = 254},
			{ypos = 1,prob = 254},
			{ypos = 2,prob = 254},
			{ypos = 3,prob = 254},
			{ypos = 4,prob = 254},
			{ypos = 5,prob = 254},
			{ypos = 6,prob = 254},
			{ypos = 7,prob = 254},
			{ypos = 8,prob = 254}
		}
	}

	lib_mg_continental.river_3x = {
		size = {x = 3, y = 7, z = 3},
		data = {
			__, __, __,
			__, __, __,
			__, __, __,
			__, __, __,
			__, aa, __,
			aa, aa, aa,
			aa, aa, aa,

			__, __, __,
			__, WW, __,
			__, WW, __,
			__, aa, __,
			__, aa, __,
			aa, aa, aa,
			aa, aa, aa,

			__, __, __,
			__, __, __,
			__, __, __,
			__, __, __,
			__, aa, __,
			aa, aa, aa,
			aa, aa, aa
		},
		yslice_prob = {
			{ypos = 0,prob = 254},
			{ypos = 1,prob = 254},
			{ypos = 2,prob = 254},
			{ypos = 3,prob = 254},
			{ypos = 4,prob = 254},
			{ypos = 5,prob = 254},
			{ypos = 6,prob = 254}
		}
	}
